
2024-11-28 16:58:22,497 -  nornir.core -     INFO -        run() - Running task 'pull_vars' with args {} on 3 hosts
2024-11-28 16:58:26,858 - nornir.core.task -    ERROR -      start() - Host 'R3': task 'send_configs' failed with traceback:
Traceback (most recent call last):
  File "/home/aliraza1278/CICD/.CICD/lib/python3.12/site-packages/nornir/core/task.py", line 99, in start
    r = self.task(self, **self.params)
        ^^^^^^^^^^^^^^^^^^^^^^^^^^^^^^
  File "/home/aliraza1278/CICD/.CICD/lib/python3.12/site-packages/nornir_scrapli/tasks/core/send_configs.py", line 59, in send_configs
    scrapli_conn = task.host.get_connection("scrapli", task.nornir.config)
                   ^^^^^^^^^^^^^^^^^^^^^^^^^^^^^^^^^^^^^^^^^^^^^^^^^^^^^^^
  File "/home/aliraza1278/CICD/.CICD/lib/python3.12/site-packages/nornir/core/inventory.py", line 494, in get_connection
    self.open_connection(
  File "/home/aliraza1278/CICD/.CICD/lib/python3.12/site-packages/nornir/core/inventory.py", line 546, in open_connection
    conn_obj.open(
  File "/home/aliraza1278/CICD/.CICD/lib/python3.12/site-packages/nornir_scrapli/connection.py", line 106, in open
    connection.open()
  File "/home/aliraza1278/CICD/.CICD/lib/python3.12/site-packages/scrapli/driver/base/sync_driver.py", line 106, in open
    self.channel.channel_authenticate_ssh(
  File "/home/aliraza1278/CICD/.CICD/lib/python3.12/site-packages/scrapli/decorators.py", line 224, in decorate
    return _multiprocessing_timeout(
           ^^^^^^^^^^^^^^^^^^^^^^^^^
  File "/home/aliraza1278/CICD/.CICD/lib/python3.12/site-packages/scrapli/decorators.py", line 115, in _multiprocessing_timeout
    return future.result()
           ^^^^^^^^^^^^^^^
  File "/usr/lib/python3.12/concurrent/futures/_base.py", line 449, in result
    return self.__get_result()
           ^^^^^^^^^^^^^^^^^^^
  File "/usr/lib/python3.12/concurrent/futures/_base.py", line 401, in __get_result
    raise self._exception
  File "/usr/lib/python3.12/concurrent/futures/thread.py", line 58, in run
    result = self.fn(*self.args, **self.kwargs)
             ^^^^^^^^^^^^^^^^^^^^^^^^^^^^^^^^^^
  File "/home/aliraza1278/CICD/.CICD/lib/python3.12/site-packages/scrapli/channel/sync_channel.py", line 309, in channel_authenticate_ssh
    raise ScrapliAuthenticationFailed(msg)
scrapli.exceptions.ScrapliAuthenticationFailed: password prompt seen more than once, assuming auth failed

2024-11-28 16:58:26,858 - nornir.core.task -    ERROR -      start() - Host 'R3': task 'pull_vars' failed with traceback:
Traceback (most recent call last):
  File "/home/aliraza1278/CICD/.CICD/lib/python3.12/site-packages/nornir/core/task.py", line 99, in start
    r = self.task(self, **self.params)
        ^^^^^^^^^^^^^^^^^^^^^^^^^^^^^^
  File "/home/aliraza1278/CICD/.CICD/Jenkins-CICD/simple1.py", line 16, in pull_vars
    push_config(task)
  File "/home/aliraza1278/CICD/.CICD/Jenkins-CICD/simple1.py", line 24, in push_config
    task.run(task=send_configs, configs=configurations)
  File "/home/aliraza1278/CICD/.CICD/lib/python3.12/site-packages/nornir/core/task.py", line 174, in run
    raise NornirSubTaskError(task=run_task, result=r)
nornir.core.exceptions.NornirSubTaskError: Subtask: send_configs (failed)


2024-11-28 16:58:26,859 - nornir.core.task -    ERROR -      start() - Host 'R2': task 'send_configs' failed with traceback:
Traceback (most recent call last):
  File "/home/aliraza1278/CICD/.CICD/lib/python3.12/site-packages/nornir/core/task.py", line 99, in start
    r = self.task(self, **self.params)
        ^^^^^^^^^^^^^^^^^^^^^^^^^^^^^^
  File "/home/aliraza1278/CICD/.CICD/lib/python3.12/site-packages/nornir_scrapli/tasks/core/send_configs.py", line 59, in send_configs
    scrapli_conn = task.host.get_connection("scrapli", task.nornir.config)
                   ^^^^^^^^^^^^^^^^^^^^^^^^^^^^^^^^^^^^^^^^^^^^^^^^^^^^^^^
  File "/home/aliraza1278/CICD/.CICD/lib/python3.12/site-packages/nornir/core/inventory.py", line 494, in get_connection
    self.open_connection(
  File "/home/aliraza1278/CICD/.CICD/lib/python3.12/site-packages/nornir/core/inventory.py", line 546, in open_connection
    conn_obj.open(
  File "/home/aliraza1278/CICD/.CICD/lib/python3.12/site-packages/nornir_scrapli/connection.py", line 106, in open
    connection.open()
  File "/home/aliraza1278/CICD/.CICD/lib/python3.12/site-packages/scrapli/driver/base/sync_driver.py", line 106, in open
    self.channel.channel_authenticate_ssh(
  File "/home/aliraza1278/CICD/.CICD/lib/python3.12/site-packages/scrapli/decorators.py", line 224, in decorate
    return _multiprocessing_timeout(
           ^^^^^^^^^^^^^^^^^^^^^^^^^
  File "/home/aliraza1278/CICD/.CICD/lib/python3.12/site-packages/scrapli/decorators.py", line 115, in _multiprocessing_timeout
    return future.result()
           ^^^^^^^^^^^^^^^
  File "/usr/lib/python3.12/concurrent/futures/_base.py", line 449, in result
    return self.__get_result()
           ^^^^^^^^^^^^^^^^^^^
  File "/usr/lib/python3.12/concurrent/futures/_base.py", line 401, in __get_result
    raise self._exception
  File "/usr/lib/python3.12/concurrent/futures/thread.py", line 58, in run
    result = self.fn(*self.args, **self.kwargs)
             ^^^^^^^^^^^^^^^^^^^^^^^^^^^^^^^^^^
  File "/home/aliraza1278/CICD/.CICD/lib/python3.12/site-packages/scrapli/channel/sync_channel.py", line 309, in channel_authenticate_ssh
    raise ScrapliAuthenticationFailed(msg)
scrapli.exceptions.ScrapliAuthenticationFailed: password prompt seen more than once, assuming auth failed

2024-11-28 16:58:26,859 - nornir.core.task -    ERROR -      start() - Host 'R2': task 'pull_vars' failed with traceback:
Traceback (most recent call last):
  File "/home/aliraza1278/CICD/.CICD/lib/python3.12/site-packages/nornir/core/task.py", line 99, in start
    r = self.task(self, **self.params)
        ^^^^^^^^^^^^^^^^^^^^^^^^^^^^^^
  File "/home/aliraza1278/CICD/.CICD/Jenkins-CICD/simple1.py", line 16, in pull_vars
    push_config(task)
  File "/home/aliraza1278/CICD/.CICD/Jenkins-CICD/simple1.py", line 24, in push_config
    task.run(task=send_configs, configs=configurations)
  File "/home/aliraza1278/CICD/.CICD/lib/python3.12/site-packages/nornir/core/task.py", line 174, in run
    raise NornirSubTaskError(task=run_task, result=r)
nornir.core.exceptions.NornirSubTaskError: Subtask: send_configs (failed)


2024-11-28 16:58:26,866 - nornir.core.task -    ERROR -      start() - Host 'R1': task 'send_configs' failed with traceback:
Traceback (most recent call last):
  File "/home/aliraza1278/CICD/.CICD/lib/python3.12/site-packages/nornir/core/task.py", line 99, in start
    r = self.task(self, **self.params)
        ^^^^^^^^^^^^^^^^^^^^^^^^^^^^^^
  File "/home/aliraza1278/CICD/.CICD/lib/python3.12/site-packages/nornir_scrapli/tasks/core/send_configs.py", line 59, in send_configs
    scrapli_conn = task.host.get_connection("scrapli", task.nornir.config)
                   ^^^^^^^^^^^^^^^^^^^^^^^^^^^^^^^^^^^^^^^^^^^^^^^^^^^^^^^
  File "/home/aliraza1278/CICD/.CICD/lib/python3.12/site-packages/nornir/core/inventory.py", line 494, in get_connection
    self.open_connection(
  File "/home/aliraza1278/CICD/.CICD/lib/python3.12/site-packages/nornir/core/inventory.py", line 546, in open_connection
    conn_obj.open(
  File "/home/aliraza1278/CICD/.CICD/lib/python3.12/site-packages/nornir_scrapli/connection.py", line 106, in open
    connection.open()
  File "/home/aliraza1278/CICD/.CICD/lib/python3.12/site-packages/scrapli/driver/base/sync_driver.py", line 106, in open
    self.channel.channel_authenticate_ssh(
  File "/home/aliraza1278/CICD/.CICD/lib/python3.12/site-packages/scrapli/decorators.py", line 224, in decorate
    return _multiprocessing_timeout(
           ^^^^^^^^^^^^^^^^^^^^^^^^^
  File "/home/aliraza1278/CICD/.CICD/lib/python3.12/site-packages/scrapli/decorators.py", line 115, in _multiprocessing_timeout
    return future.result()
           ^^^^^^^^^^^^^^^
  File "/usr/lib/python3.12/concurrent/futures/_base.py", line 449, in result
    return self.__get_result()
           ^^^^^^^^^^^^^^^^^^^
  File "/usr/lib/python3.12/concurrent/futures/_base.py", line 401, in __get_result
    raise self._exception
  File "/usr/lib/python3.12/concurrent/futures/thread.py", line 58, in run
    result = self.fn(*self.args, **self.kwargs)
             ^^^^^^^^^^^^^^^^^^^^^^^^^^^^^^^^^^
  File "/home/aliraza1278/CICD/.CICD/lib/python3.12/site-packages/scrapli/channel/sync_channel.py", line 309, in channel_authenticate_ssh
    raise ScrapliAuthenticationFailed(msg)
scrapli.exceptions.ScrapliAuthenticationFailed: password prompt seen more than once, assuming auth failed

2024-11-28 16:58:26,866 - nornir.core.task -    ERROR -      start() - Host 'R1': task 'pull_vars' failed with traceback:
Traceback (most recent call last):
  File "/home/aliraza1278/CICD/.CICD/lib/python3.12/site-packages/nornir/core/task.py", line 99, in start
    r = self.task(self, **self.params)
        ^^^^^^^^^^^^^^^^^^^^^^^^^^^^^^
  File "/home/aliraza1278/CICD/.CICD/Jenkins-CICD/simple1.py", line 16, in pull_vars
    push_config(task)
  File "/home/aliraza1278/CICD/.CICD/Jenkins-CICD/simple1.py", line 24, in push_config
    task.run(task=send_configs, configs=configurations)
  File "/home/aliraza1278/CICD/.CICD/lib/python3.12/site-packages/nornir/core/task.py", line 174, in run
    raise NornirSubTaskError(task=run_task, result=r)
nornir.core.exceptions.NornirSubTaskError: Subtask: send_configs (failed)


2024-11-28 16:59:28,334 -  nornir.core -     INFO -        run() - Running task 'pull_vars' with args {} on 3 hosts
2024-11-28 16:59:32,688 - nornir.core.task -    ERROR -      start() - Host 'R1': task 'send_configs' failed with traceback:
Traceback (most recent call last):
  File "/home/aliraza1278/CICD/.CICD/lib/python3.12/site-packages/nornir/core/task.py", line 99, in start
    r = self.task(self, **self.params)
        ^^^^^^^^^^^^^^^^^^^^^^^^^^^^^^
  File "/home/aliraza1278/CICD/.CICD/lib/python3.12/site-packages/nornir_scrapli/tasks/core/send_configs.py", line 59, in send_configs
    scrapli_conn = task.host.get_connection("scrapli", task.nornir.config)
                   ^^^^^^^^^^^^^^^^^^^^^^^^^^^^^^^^^^^^^^^^^^^^^^^^^^^^^^^
  File "/home/aliraza1278/CICD/.CICD/lib/python3.12/site-packages/nornir/core/inventory.py", line 494, in get_connection
    self.open_connection(
  File "/home/aliraza1278/CICD/.CICD/lib/python3.12/site-packages/nornir/core/inventory.py", line 546, in open_connection
    conn_obj.open(
  File "/home/aliraza1278/CICD/.CICD/lib/python3.12/site-packages/nornir_scrapli/connection.py", line 106, in open
    connection.open()
  File "/home/aliraza1278/CICD/.CICD/lib/python3.12/site-packages/scrapli/driver/base/sync_driver.py", line 106, in open
    self.channel.channel_authenticate_ssh(
  File "/home/aliraza1278/CICD/.CICD/lib/python3.12/site-packages/scrapli/decorators.py", line 224, in decorate
    return _multiprocessing_timeout(
           ^^^^^^^^^^^^^^^^^^^^^^^^^
  File "/home/aliraza1278/CICD/.CICD/lib/python3.12/site-packages/scrapli/decorators.py", line 115, in _multiprocessing_timeout
    return future.result()
           ^^^^^^^^^^^^^^^
  File "/usr/lib/python3.12/concurrent/futures/_base.py", line 449, in result
    return self.__get_result()
           ^^^^^^^^^^^^^^^^^^^
  File "/usr/lib/python3.12/concurrent/futures/_base.py", line 401, in __get_result
    raise self._exception
  File "/usr/lib/python3.12/concurrent/futures/thread.py", line 58, in run
    result = self.fn(*self.args, **self.kwargs)
             ^^^^^^^^^^^^^^^^^^^^^^^^^^^^^^^^^^
  File "/home/aliraza1278/CICD/.CICD/lib/python3.12/site-packages/scrapli/channel/sync_channel.py", line 309, in channel_authenticate_ssh
    raise ScrapliAuthenticationFailed(msg)
scrapli.exceptions.ScrapliAuthenticationFailed: password prompt seen more than once, assuming auth failed

2024-11-28 16:59:32,688 - nornir.core.task -    ERROR -      start() - Host 'R1': task 'pull_vars' failed with traceback:
Traceback (most recent call last):
  File "/home/aliraza1278/CICD/.CICD/lib/python3.12/site-packages/nornir/core/task.py", line 99, in start
    r = self.task(self, **self.params)
        ^^^^^^^^^^^^^^^^^^^^^^^^^^^^^^
  File "/home/aliraza1278/CICD/.CICD/Jenkins-CICD/simple1.py", line 16, in pull_vars
    push_config(task)
  File "/home/aliraza1278/CICD/.CICD/Jenkins-CICD/simple1.py", line 24, in push_config
    task.run(task=send_configs, configs=configurations)
  File "/home/aliraza1278/CICD/.CICD/lib/python3.12/site-packages/nornir/core/task.py", line 174, in run
    raise NornirSubTaskError(task=run_task, result=r)
nornir.core.exceptions.NornirSubTaskError: Subtask: send_configs (failed)


2024-11-28 16:59:32,693 - nornir.core.task -    ERROR -      start() - Host 'R3': task 'send_configs' failed with traceback:
Traceback (most recent call last):
  File "/home/aliraza1278/CICD/.CICD/lib/python3.12/site-packages/nornir/core/task.py", line 99, in start
    r = self.task(self, **self.params)
        ^^^^^^^^^^^^^^^^^^^^^^^^^^^^^^
  File "/home/aliraza1278/CICD/.CICD/lib/python3.12/site-packages/nornir_scrapli/tasks/core/send_configs.py", line 59, in send_configs
    scrapli_conn = task.host.get_connection("scrapli", task.nornir.config)
                   ^^^^^^^^^^^^^^^^^^^^^^^^^^^^^^^^^^^^^^^^^^^^^^^^^^^^^^^
  File "/home/aliraza1278/CICD/.CICD/lib/python3.12/site-packages/nornir/core/inventory.py", line 494, in get_connection
    self.open_connection(
  File "/home/aliraza1278/CICD/.CICD/lib/python3.12/site-packages/nornir/core/inventory.py", line 546, in open_connection
    conn_obj.open(
  File "/home/aliraza1278/CICD/.CICD/lib/python3.12/site-packages/nornir_scrapli/connection.py", line 106, in open
    connection.open()
  File "/home/aliraza1278/CICD/.CICD/lib/python3.12/site-packages/scrapli/driver/base/sync_driver.py", line 106, in open
    self.channel.channel_authenticate_ssh(
  File "/home/aliraza1278/CICD/.CICD/lib/python3.12/site-packages/scrapli/decorators.py", line 224, in decorate
    return _multiprocessing_timeout(
           ^^^^^^^^^^^^^^^^^^^^^^^^^
  File "/home/aliraza1278/CICD/.CICD/lib/python3.12/site-packages/scrapli/decorators.py", line 115, in _multiprocessing_timeout
    return future.result()
           ^^^^^^^^^^^^^^^
  File "/usr/lib/python3.12/concurrent/futures/_base.py", line 449, in result
    return self.__get_result()
           ^^^^^^^^^^^^^^^^^^^
  File "/usr/lib/python3.12/concurrent/futures/_base.py", line 401, in __get_result
    raise self._exception
  File "/usr/lib/python3.12/concurrent/futures/thread.py", line 58, in run
    result = self.fn(*self.args, **self.kwargs)
             ^^^^^^^^^^^^^^^^^^^^^^^^^^^^^^^^^^
  File "/home/aliraza1278/CICD/.CICD/lib/python3.12/site-packages/scrapli/channel/sync_channel.py", line 309, in channel_authenticate_ssh
    raise ScrapliAuthenticationFailed(msg)
scrapli.exceptions.ScrapliAuthenticationFailed: password prompt seen more than once, assuming auth failed

2024-11-28 16:59:32,693 - nornir.core.task -    ERROR -      start() - Host 'R3': task 'pull_vars' failed with traceback:
Traceback (most recent call last):
  File "/home/aliraza1278/CICD/.CICD/lib/python3.12/site-packages/nornir/core/task.py", line 99, in start
    r = self.task(self, **self.params)
        ^^^^^^^^^^^^^^^^^^^^^^^^^^^^^^
  File "/home/aliraza1278/CICD/.CICD/Jenkins-CICD/simple1.py", line 16, in pull_vars
    push_config(task)
  File "/home/aliraza1278/CICD/.CICD/Jenkins-CICD/simple1.py", line 24, in push_config
    task.run(task=send_configs, configs=configurations)
  File "/home/aliraza1278/CICD/.CICD/lib/python3.12/site-packages/nornir/core/task.py", line 174, in run
    raise NornirSubTaskError(task=run_task, result=r)
nornir.core.exceptions.NornirSubTaskError: Subtask: send_configs (failed)


2024-11-28 16:59:32,709 - nornir.core.task -    ERROR -      start() - Host 'R2': task 'send_configs' failed with traceback:
Traceback (most recent call last):
  File "/home/aliraza1278/CICD/.CICD/lib/python3.12/site-packages/nornir/core/task.py", line 99, in start
    r = self.task(self, **self.params)
        ^^^^^^^^^^^^^^^^^^^^^^^^^^^^^^
  File "/home/aliraza1278/CICD/.CICD/lib/python3.12/site-packages/nornir_scrapli/tasks/core/send_configs.py", line 59, in send_configs
    scrapli_conn = task.host.get_connection("scrapli", task.nornir.config)
                   ^^^^^^^^^^^^^^^^^^^^^^^^^^^^^^^^^^^^^^^^^^^^^^^^^^^^^^^
  File "/home/aliraza1278/CICD/.CICD/lib/python3.12/site-packages/nornir/core/inventory.py", line 494, in get_connection
    self.open_connection(
  File "/home/aliraza1278/CICD/.CICD/lib/python3.12/site-packages/nornir/core/inventory.py", line 546, in open_connection
    conn_obj.open(
  File "/home/aliraza1278/CICD/.CICD/lib/python3.12/site-packages/nornir_scrapli/connection.py", line 106, in open
    connection.open()
  File "/home/aliraza1278/CICD/.CICD/lib/python3.12/site-packages/scrapli/driver/base/sync_driver.py", line 106, in open
    self.channel.channel_authenticate_ssh(
  File "/home/aliraza1278/CICD/.CICD/lib/python3.12/site-packages/scrapli/decorators.py", line 224, in decorate
    return _multiprocessing_timeout(
           ^^^^^^^^^^^^^^^^^^^^^^^^^
  File "/home/aliraza1278/CICD/.CICD/lib/python3.12/site-packages/scrapli/decorators.py", line 115, in _multiprocessing_timeout
    return future.result()
           ^^^^^^^^^^^^^^^
  File "/usr/lib/python3.12/concurrent/futures/_base.py", line 449, in result
    return self.__get_result()
           ^^^^^^^^^^^^^^^^^^^
  File "/usr/lib/python3.12/concurrent/futures/_base.py", line 401, in __get_result
    raise self._exception
  File "/usr/lib/python3.12/concurrent/futures/thread.py", line 58, in run
    result = self.fn(*self.args, **self.kwargs)
             ^^^^^^^^^^^^^^^^^^^^^^^^^^^^^^^^^^
  File "/home/aliraza1278/CICD/.CICD/lib/python3.12/site-packages/scrapli/channel/sync_channel.py", line 309, in channel_authenticate_ssh
    raise ScrapliAuthenticationFailed(msg)
scrapli.exceptions.ScrapliAuthenticationFailed: password prompt seen more than once, assuming auth failed

2024-11-28 16:59:32,709 - nornir.core.task -    ERROR -      start() - Host 'R2': task 'pull_vars' failed with traceback:
Traceback (most recent call last):
  File "/home/aliraza1278/CICD/.CICD/lib/python3.12/site-packages/nornir/core/task.py", line 99, in start
    r = self.task(self, **self.params)
        ^^^^^^^^^^^^^^^^^^^^^^^^^^^^^^
  File "/home/aliraza1278/CICD/.CICD/Jenkins-CICD/simple1.py", line 16, in pull_vars
    push_config(task)
  File "/home/aliraza1278/CICD/.CICD/Jenkins-CICD/simple1.py", line 24, in push_config
    task.run(task=send_configs, configs=configurations)
  File "/home/aliraza1278/CICD/.CICD/lib/python3.12/site-packages/nornir/core/task.py", line 174, in run
    raise NornirSubTaskError(task=run_task, result=r)
nornir.core.exceptions.NornirSubTaskError: Subtask: send_configs (failed)


2024-11-28 17:04:40,395 -  nornir.core -     INFO -        run() - Running task 'pull_vars' with args {} on 3 hosts
2024-11-28 17:04:44,775 - nornir.core.task -    ERROR -      start() - Host 'R2': task 'send_configs' failed with traceback:
Traceback (most recent call last):
  File "/home/aliraza1278/CICD/.CICD/lib/python3.12/site-packages/nornir/core/task.py", line 99, in start
    r = self.task(self, **self.params)
        ^^^^^^^^^^^^^^^^^^^^^^^^^^^^^^
  File "/home/aliraza1278/CICD/.CICD/lib/python3.12/site-packages/nornir_scrapli/tasks/core/send_configs.py", line 59, in send_configs
    scrapli_conn = task.host.get_connection("scrapli", task.nornir.config)
                   ^^^^^^^^^^^^^^^^^^^^^^^^^^^^^^^^^^^^^^^^^^^^^^^^^^^^^^^
  File "/home/aliraza1278/CICD/.CICD/lib/python3.12/site-packages/nornir/core/inventory.py", line 494, in get_connection
    self.open_connection(
  File "/home/aliraza1278/CICD/.CICD/lib/python3.12/site-packages/nornir/core/inventory.py", line 546, in open_connection
    conn_obj.open(
  File "/home/aliraza1278/CICD/.CICD/lib/python3.12/site-packages/nornir_scrapli/connection.py", line 106, in open
    connection.open()
  File "/home/aliraza1278/CICD/.CICD/lib/python3.12/site-packages/scrapli/driver/base/sync_driver.py", line 106, in open
    self.channel.channel_authenticate_ssh(
  File "/home/aliraza1278/CICD/.CICD/lib/python3.12/site-packages/scrapli/decorators.py", line 224, in decorate
    return _multiprocessing_timeout(
           ^^^^^^^^^^^^^^^^^^^^^^^^^
  File "/home/aliraza1278/CICD/.CICD/lib/python3.12/site-packages/scrapli/decorators.py", line 115, in _multiprocessing_timeout
    return future.result()
           ^^^^^^^^^^^^^^^
  File "/usr/lib/python3.12/concurrent/futures/_base.py", line 449, in result
    return self.__get_result()
           ^^^^^^^^^^^^^^^^^^^
  File "/usr/lib/python3.12/concurrent/futures/_base.py", line 401, in __get_result
    raise self._exception
  File "/usr/lib/python3.12/concurrent/futures/thread.py", line 58, in run
    result = self.fn(*self.args, **self.kwargs)
             ^^^^^^^^^^^^^^^^^^^^^^^^^^^^^^^^^^
  File "/home/aliraza1278/CICD/.CICD/lib/python3.12/site-packages/scrapli/channel/sync_channel.py", line 309, in channel_authenticate_ssh
    raise ScrapliAuthenticationFailed(msg)
scrapli.exceptions.ScrapliAuthenticationFailed: password prompt seen more than once, assuming auth failed

2024-11-28 17:04:44,775 - nornir.core.task -    ERROR -      start() - Host 'R2': task 'pull_vars' failed with traceback:
Traceback (most recent call last):
  File "/home/aliraza1278/CICD/.CICD/lib/python3.12/site-packages/nornir/core/task.py", line 99, in start
    r = self.task(self, **self.params)
        ^^^^^^^^^^^^^^^^^^^^^^^^^^^^^^
  File "/home/aliraza1278/CICD/.CICD/Jenkins-CICD/simple1.py", line 16, in pull_vars
    push_config(task)
  File "/home/aliraza1278/CICD/.CICD/Jenkins-CICD/simple1.py", line 24, in push_config
    task.run(task=send_configs, configs=configurations)
  File "/home/aliraza1278/CICD/.CICD/lib/python3.12/site-packages/nornir/core/task.py", line 174, in run
    raise NornirSubTaskError(task=run_task, result=r)
nornir.core.exceptions.NornirSubTaskError: Subtask: send_configs (failed)


2024-11-28 17:04:44,776 - nornir.core.task -    ERROR -      start() - Host 'R3': task 'send_configs' failed with traceback:
Traceback (most recent call last):
  File "/home/aliraza1278/CICD/.CICD/lib/python3.12/site-packages/nornir/core/task.py", line 99, in start
    r = self.task(self, **self.params)
        ^^^^^^^^^^^^^^^^^^^^^^^^^^^^^^
  File "/home/aliraza1278/CICD/.CICD/lib/python3.12/site-packages/nornir_scrapli/tasks/core/send_configs.py", line 59, in send_configs
    scrapli_conn = task.host.get_connection("scrapli", task.nornir.config)
                   ^^^^^^^^^^^^^^^^^^^^^^^^^^^^^^^^^^^^^^^^^^^^^^^^^^^^^^^
  File "/home/aliraza1278/CICD/.CICD/lib/python3.12/site-packages/nornir/core/inventory.py", line 494, in get_connection
    self.open_connection(
  File "/home/aliraza1278/CICD/.CICD/lib/python3.12/site-packages/nornir/core/inventory.py", line 546, in open_connection
    conn_obj.open(
  File "/home/aliraza1278/CICD/.CICD/lib/python3.12/site-packages/nornir_scrapli/connection.py", line 106, in open
    connection.open()
  File "/home/aliraza1278/CICD/.CICD/lib/python3.12/site-packages/scrapli/driver/base/sync_driver.py", line 106, in open
    self.channel.channel_authenticate_ssh(
  File "/home/aliraza1278/CICD/.CICD/lib/python3.12/site-packages/scrapli/decorators.py", line 224, in decorate
    return _multiprocessing_timeout(
           ^^^^^^^^^^^^^^^^^^^^^^^^^
  File "/home/aliraza1278/CICD/.CICD/lib/python3.12/site-packages/scrapli/decorators.py", line 115, in _multiprocessing_timeout
    return future.result()
           ^^^^^^^^^^^^^^^
  File "/usr/lib/python3.12/concurrent/futures/_base.py", line 449, in result
    return self.__get_result()
           ^^^^^^^^^^^^^^^^^^^
  File "/usr/lib/python3.12/concurrent/futures/_base.py", line 401, in __get_result
    raise self._exception
  File "/usr/lib/python3.12/concurrent/futures/thread.py", line 58, in run
    result = self.fn(*self.args, **self.kwargs)
             ^^^^^^^^^^^^^^^^^^^^^^^^^^^^^^^^^^
  File "/home/aliraza1278/CICD/.CICD/lib/python3.12/site-packages/scrapli/channel/sync_channel.py", line 309, in channel_authenticate_ssh
    raise ScrapliAuthenticationFailed(msg)
scrapli.exceptions.ScrapliAuthenticationFailed: password prompt seen more than once, assuming auth failed

2024-11-28 17:04:44,776 - nornir.core.task -    ERROR -      start() - Host 'R3': task 'pull_vars' failed with traceback:
Traceback (most recent call last):
  File "/home/aliraza1278/CICD/.CICD/lib/python3.12/site-packages/nornir/core/task.py", line 99, in start
    r = self.task(self, **self.params)
        ^^^^^^^^^^^^^^^^^^^^^^^^^^^^^^
  File "/home/aliraza1278/CICD/.CICD/Jenkins-CICD/simple1.py", line 16, in pull_vars
    push_config(task)
  File "/home/aliraza1278/CICD/.CICD/Jenkins-CICD/simple1.py", line 24, in push_config
    task.run(task=send_configs, configs=configurations)
  File "/home/aliraza1278/CICD/.CICD/lib/python3.12/site-packages/nornir/core/task.py", line 174, in run
    raise NornirSubTaskError(task=run_task, result=r)
nornir.core.exceptions.NornirSubTaskError: Subtask: send_configs (failed)


2024-11-28 17:04:44,811 - nornir.core.task -    ERROR -      start() - Host 'R1': task 'send_configs' failed with traceback:
Traceback (most recent call last):
  File "/home/aliraza1278/CICD/.CICD/lib/python3.12/site-packages/nornir/core/task.py", line 99, in start
    r = self.task(self, **self.params)
        ^^^^^^^^^^^^^^^^^^^^^^^^^^^^^^
  File "/home/aliraza1278/CICD/.CICD/lib/python3.12/site-packages/nornir_scrapli/tasks/core/send_configs.py", line 59, in send_configs
    scrapli_conn = task.host.get_connection("scrapli", task.nornir.config)
                   ^^^^^^^^^^^^^^^^^^^^^^^^^^^^^^^^^^^^^^^^^^^^^^^^^^^^^^^
  File "/home/aliraza1278/CICD/.CICD/lib/python3.12/site-packages/nornir/core/inventory.py", line 494, in get_connection
    self.open_connection(
  File "/home/aliraza1278/CICD/.CICD/lib/python3.12/site-packages/nornir/core/inventory.py", line 546, in open_connection
    conn_obj.open(
  File "/home/aliraza1278/CICD/.CICD/lib/python3.12/site-packages/nornir_scrapli/connection.py", line 106, in open
    connection.open()
  File "/home/aliraza1278/CICD/.CICD/lib/python3.12/site-packages/scrapli/driver/base/sync_driver.py", line 106, in open
    self.channel.channel_authenticate_ssh(
  File "/home/aliraza1278/CICD/.CICD/lib/python3.12/site-packages/scrapli/decorators.py", line 224, in decorate
    return _multiprocessing_timeout(
           ^^^^^^^^^^^^^^^^^^^^^^^^^
  File "/home/aliraza1278/CICD/.CICD/lib/python3.12/site-packages/scrapli/decorators.py", line 115, in _multiprocessing_timeout
    return future.result()
           ^^^^^^^^^^^^^^^
  File "/usr/lib/python3.12/concurrent/futures/_base.py", line 449, in result
    return self.__get_result()
           ^^^^^^^^^^^^^^^^^^^
  File "/usr/lib/python3.12/concurrent/futures/_base.py", line 401, in __get_result
    raise self._exception
  File "/usr/lib/python3.12/concurrent/futures/thread.py", line 58, in run
    result = self.fn(*self.args, **self.kwargs)
             ^^^^^^^^^^^^^^^^^^^^^^^^^^^^^^^^^^
  File "/home/aliraza1278/CICD/.CICD/lib/python3.12/site-packages/scrapli/channel/sync_channel.py", line 309, in channel_authenticate_ssh
    raise ScrapliAuthenticationFailed(msg)
scrapli.exceptions.ScrapliAuthenticationFailed: password prompt seen more than once, assuming auth failed

2024-11-28 17:04:44,811 - nornir.core.task -    ERROR -      start() - Host 'R1': task 'pull_vars' failed with traceback:
Traceback (most recent call last):
  File "/home/aliraza1278/CICD/.CICD/lib/python3.12/site-packages/nornir/core/task.py", line 99, in start
    r = self.task(self, **self.params)
        ^^^^^^^^^^^^^^^^^^^^^^^^^^^^^^
  File "/home/aliraza1278/CICD/.CICD/Jenkins-CICD/simple1.py", line 16, in pull_vars
    push_config(task)
  File "/home/aliraza1278/CICD/.CICD/Jenkins-CICD/simple1.py", line 24, in push_config
    task.run(task=send_configs, configs=configurations)
  File "/home/aliraza1278/CICD/.CICD/lib/python3.12/site-packages/nornir/core/task.py", line 174, in run
    raise NornirSubTaskError(task=run_task, result=r)
nornir.core.exceptions.NornirSubTaskError: Subtask: send_configs (failed)


2024-11-28 17:21:26,431 -  nornir.core -     INFO -        run() - Running task 'pull_vars' with args {} on 3 hosts
2024-11-28 17:22:00,208 -  nornir.core -     INFO -        run() - Running task 'pull_vars' with args {} on 3 hosts
2024-11-28 17:23:34,692 -  nornir.core -     INFO -        run() - Running task 'pull_vars' with args {} on 3 hosts
